## **오류는 언제 발생하는가?**

아래는 실제 프로그램에서 자주 발생하는 오류 3가지 예시이다.

### **1.  존재하지 않은 파일을 사용하려고 할 때**

```python
>>> f = open("존재하지 않는 파일", 'r')
Traceback (most recent call last):
  File "<stdin>", line 1, in <module>
FileNotFoundError: [Errno 2] No such file or directory: '존재하지 않는 파일'
```

### **2. 어떠한 수를 0으로 나눌려고 할 때**

```python
>>> 4 / 0 
Traceback (most recent call last):
  File "<stdin>", line 1, in <module>
ZeroDivisionError: division by zero
```

### **3. 리스트의 인데스 범위를 벗어났을 때**

```python
>>> a = [1,2,3]
>>> a[3]
Traceback (most recent call last):
  File "<stdin>", line 1, in <module>
IndexError: list index out of range
```

## **오류 예외 처리 기법**

### **try-except 문**

```python
# 기본 구조 
try:
	...
except [발생오류 [as 오류변수]]:
	... 
```

위 코드는 try-except문의 기본 구조로 try 블록에서 오류가 발생하면 except 블록이 수행된다. 

만약 try 블록에서 오류가 발생하지 않는다면 execpt 블록은 실행되지 않는다.

except 구문을 자세히 살펴보면 대괄호 `[]`  를 사용하는데, 이는 괄호 안의 내용을 생략할 수 있는 관례적인 표기법이다.

except 구문은 다음과 같은 3가지 방법으로 사용할 수 있다.

**1. try-except만 쓰는 방법**

```python
try:
	...
except:
	...
```

이 경우에는 오류의 종류와 상관없이 오류 발생시 바로 except 블록을 수행한다.

**2. 발생한 오류만 포함한 except 문**

```python
try:
	...
except 발생오류:
	...
```

이 경우에는 오류가 발생했을때 except문에 미리 정의해 둔 오류에 대해서만 처리한다.

**3. 발생한 오류와 변수까지 포함한 except 문**

```python
try:
	...
except 발생오류 as 오류변수
	...
```

이 경우 except 블록에서 발생한 오류의 내용까지 알고 싶을때 사용한다.

3번째 방법의 예를 한번 들어보겠다.

```python
# try_except.py
try:
	4 / 0
except ZeroDivisionError as e:
	print(e)
```

위 처럼 4를 0으로 나누려고 했을때 ZeroDivistionErrorr가 발생하여 except 블록이 실행이 되고 ‘e’ 라는 오류 변수에 저장후 출력하는 코드이다. print문으로 오류 변수를 출력하면 다음과 같은 오류 메세지가 출력된다.

```python
division by zero
```

### **try-finally 문**

try 문에는 finally 절을 사용할 수 있다. finally 절은 try 문 수행 도중 예외 발생 여부에 상관없이 항상 수행된다.

보통 finally 절은 사용한 리소스를 종료해야 할 때 많이 사용한다.

다음 예를 통해 try-finally 문의 기본 구조를 살펴보자.

```python
# try_finally.py

try:
	f = open("openFile", 'w')
	# 무언갈 수행한다.
	# 	(...생략...)

finally:
	f.close()
```

위 경우 파일을 쓰기 모드로 연 후 예외 발생 여부와 상관없이, 파일을 닫기 위해서 finally문을 사용해 주면 된다.

### **여러 개의 오류 처리하기**

try 문 안에서 여러개의 오류를 처리하려면 다음과 같이 사용해야 한다.

```python
try:
	...
except 발생오류1:
	...
except 발생오류2:
	...
except 발생오류3:
	...
```

(기본 구조)

(EX)

```python
# many_error.py
try:
	a = [1,2]
	print(a[2])
	4/0

except IndexError:
	print("인덱싱 할 수 없습니다.")

except ZeroDivisionError:
	print("0으로 나눌 수 없습니다.")
```

위 예제는 IndexError 와 ZeroDivisitonError 두개의 오류의 예외처리 코드를 작성하였다.

try 블록에서 IndexError가 가장 먼저 발생하므로 `4 / 0` 에 따른 ZeroDivisionError는 발생하지 않는다.

```python
try:
	a = [1,2]
	print(a[2])
	4/0
except(IndexError, ZeroDivision) as e
print(e)
```

2개 이상의 오류를 동일하기 위해선, 위와 같이 괄호를 사용하여 함께 묶어 처리하면 된다.

### **try-else**

try-else문은 try문에서 오류가 발생하면 except 블록이 실행되고 그렇지 않으면 else문을 실행한다.

```python
try:
    ...
except [발생오류 [as 오류변수]]:
    ...
else:  # 오류가 없을 경우에만 수행
    ...
```

### **오류 일부러 회피하기**

우리는 종종 프로그래밍을 하다보면 일부러 오류를 발생시켜야 할 경우가 생긴다. 이런경우를 대비하여 파이썬에서는 `raise` 명령어를 사용해 오류를 강제 발생시킬 수 있다.

예를 들어 Shoes 클래스를 상속받는 자식 클래스는 반드시 color라는 함수를 구현하도록 만들고 싶을 수도 있다.

```python
# error_raise.py
class Shoes:
	def color(self):
		raise NotImplementError
```

위와 같이 Shoes 클래스를 정의하였다. 

그럼 만약 Shoes 클래스를 상속 받는 자식 클래스가 color 함수를 구현하지 않으면 어떻게 될까?

```python
class Nike:
	def color(self):
		pass

shoes = Nike()
shoes.color()
```

Nike 클래스는 Shoes 클래스를 상속받은 자식 클래스이다.

그런데 Nike 클래스는 부모 클래스인 Shoes 클래스를 color 메서드를 오버라이딩하여 구현하지 않았다. 따라서 shoes 객체의 color 메서드를 실행하는 순간 error가 발생하는 것이다.

오류가 발생하지 않도록 하려면 다음과 같이 코드를 작성해야 한다.

```python
class Nike:
	def color(self):
		print("빨간색 입니다.")

shoes = Nike()
shoes.color()

# 출력 결과 -> "빨간색 입니다."
```

## **예외 만들기**

프로그래밍을 하다가 가끔 특수한 경우를 마주칠 때가 있다. 이런 경우 예외 처리를 하기 위해 따로 예외를 만들어 사용한다.

```python
# error_make.py
class MyError(Exception):
	pass
```

```python
# 함수 작성
def say_minseo(minseo):
	if minseo == "바보":
			raise MyError()
	print(minseo)
```

```python
# 함수 호출
say_minseo("멍충멍충")
say_minseo("똑똑!")
say_minseo("바보")
```

위와 같이 클래스, 함수, 함수 호출 코드를 작성후 실행해 보면 “멍충멍충”, “똑똑!”이 출력되고, 오류가 발생하는 것을 알 수 있다.

이번에는 예외 처리 기법을 사용하여 MyError 발생을 예외 처리 하겠다.

```python
try:
    say_minseo("멍충멍충")
    say_minseo("똑똑!")
		say_minseo("바보")
except MyError:
    print("허용되지 않는 별명입니다.")
```

프로그램을 실행하면 “멍충멍충”, “똑똑!”은 아까와 같이 출력되고, “바보”가 출력되야 하는 부분에서는 “허용되지 않은 별명” 이라고 출력이 된다.

만약 오류 메시지를 사용하고 싶다면 다음과 같이 예외 처리를 하면 된다.

```python
try:
    say_minseo("멍충멍충")
    say_minseo("똑똑!")
		say_minseo("바보")
except MyError as e:
    print(e)
```

하지만 이 경우엔 print(e)로 오류 메시지가 출력되지 않은 것을 확인할 수 있다. 오류 메시지를 출력했을 때 오류 메시지가 보이게 하려면, MyError 클래스에 `__str__` 메서드를 구현해야 한다.

```python
class MyError(minseo):
	def __str__(self):
			return "허용되지 않은 별명입니다."
```